[2021-11-21 20:17:20,363] {taskinstance.py:1035} INFO - Dependencies all met for <TaskInstance: DWBI_HW2_dag.transform manual__2021-11-21T19:17:17.384479+00:00 [queued]>
[2021-11-21 20:17:20,370] {taskinstance.py:1035} INFO - Dependencies all met for <TaskInstance: DWBI_HW2_dag.transform manual__2021-11-21T19:17:17.384479+00:00 [queued]>
[2021-11-21 20:17:20,370] {taskinstance.py:1241} INFO - 
--------------------------------------------------------------------------------
[2021-11-21 20:17:20,370] {taskinstance.py:1242} INFO - Starting attempt 1 of 6
[2021-11-21 20:17:20,370] {taskinstance.py:1243} INFO - 
--------------------------------------------------------------------------------
[2021-11-21 20:17:20,382] {taskinstance.py:1262} INFO - Executing <Task(_PythonDecoratedOperator): transform> on 2021-11-21 19:17:17.384479+00:00
[2021-11-21 20:17:20,385] {standard_task_runner.py:52} INFO - Started process 17185 to run task
[2021-11-21 20:17:20,388] {standard_task_runner.py:76} INFO - Running: ['airflow', 'tasks', 'run', 'DWBI_HW2_dag', 'transform', 'manual__2021-11-21T19:17:17.384479+00:00', '--job-id', '18', '--raw', '--subdir', '/home/dante/DWBI/Apache/dags/DWBI_HW2_dag.py', '--cfg-path', '/tmp/tmp8l92dyjh', '--error-file', '/tmp/tmpfyihugd4']
[2021-11-21 20:17:20,389] {standard_task_runner.py:77} INFO - Job 18: Subtask transform
[2021-11-21 20:17:20,418] {logging_mixin.py:109} INFO - Running <TaskInstance: DWBI_HW2_dag.transform manual__2021-11-21T19:17:17.384479+00:00 [running]> on host dj-XPS
[2021-11-21 20:17:20,446] {taskinstance.py:1427} INFO - Exporting the following env vars:
AIRFLOW_CTX_DAG_OWNER=dj
AIRFLOW_CTX_DAG_ID=DWBI_HW2_dag
AIRFLOW_CTX_TASK_ID=transform
AIRFLOW_CTX_EXECUTION_DATE=2021-11-21T19:17:17.384479+00:00
AIRFLOW_CTX_DAG_RUN_ID=manual__2021-11-21T19:17:17.384479+00:00
[2021-11-21 20:17:20,447] {taskinstance.py:1703} ERROR - Task failed with exception
Traceback (most recent call last):
  File "/home/dante/DWBI/Apache/py_env/lib/python3.8/site-packages/airflow/models/taskinstance.py", line 1332, in _run_raw_task
    self._execute_task_with_callbacks(context)
  File "/home/dante/DWBI/Apache/py_env/lib/python3.8/site-packages/airflow/models/taskinstance.py", line 1458, in _execute_task_with_callbacks
    result = self._execute_task(context, self.task)
  File "/home/dante/DWBI/Apache/py_env/lib/python3.8/site-packages/airflow/models/taskinstance.py", line 1514, in _execute_task
    result = execute_callable(context=context)
  File "/home/dante/DWBI/Apache/py_env/lib/python3.8/site-packages/airflow/decorators/base.py", line 134, in execute
    return_value = super().execute(context)
  File "/home/dante/DWBI/Apache/py_env/lib/python3.8/site-packages/airflow/operators/python.py", line 151, in execute
    return_value = self.execute_callable()
  File "/home/dante/DWBI/Apache/py_env/lib/python3.8/site-packages/airflow/operators/python.py", line 162, in execute_callable
    return self.python_callable(*self.op_args, **self.op_kwargs)
  File "/home/dante/DWBI/Apache/dags/DWBI_HW2_dag.py", line 47, in transform
    dat_2 = data.drop(columns=[['VIN','FuelType']])
AttributeError: 'function' object has no attribute 'drop'
[2021-11-21 20:17:20,453] {taskinstance.py:1270} INFO - Marking task as UP_FOR_RETRY. dag_id=DWBI_HW2_dag, task_id=transform, execution_date=20211121T191717, start_date=20211121T191720, end_date=20211121T191720
[2021-11-21 20:17:20,466] {standard_task_runner.py:88} ERROR - Failed to execute job 18 for task transform
Traceback (most recent call last):
  File "/home/dante/DWBI/Apache/py_env/lib/python3.8/site-packages/airflow/task/task_runner/standard_task_runner.py", line 85, in _start_by_fork
    args.func(args, dag=self.dag)
  File "/home/dante/DWBI/Apache/py_env/lib/python3.8/site-packages/airflow/cli/cli_parser.py", line 48, in command
    return func(*args, **kwargs)
  File "/home/dante/DWBI/Apache/py_env/lib/python3.8/site-packages/airflow/utils/cli.py", line 92, in wrapper
    return f(*args, **kwargs)
  File "/home/dante/DWBI/Apache/py_env/lib/python3.8/site-packages/airflow/cli/commands/task_command.py", line 292, in task_run
    _run_task_by_selected_method(args, dag, ti)
  File "/home/dante/DWBI/Apache/py_env/lib/python3.8/site-packages/airflow/cli/commands/task_command.py", line 107, in _run_task_by_selected_method
    _run_raw_task(args, ti)
  File "/home/dante/DWBI/Apache/py_env/lib/python3.8/site-packages/airflow/cli/commands/task_command.py", line 180, in _run_raw_task
    ti._run_raw_task(
  File "/home/dante/DWBI/Apache/py_env/lib/python3.8/site-packages/airflow/utils/session.py", line 70, in wrapper
    return func(*args, session=session, **kwargs)
  File "/home/dante/DWBI/Apache/py_env/lib/python3.8/site-packages/airflow/models/taskinstance.py", line 1332, in _run_raw_task
    self._execute_task_with_callbacks(context)
  File "/home/dante/DWBI/Apache/py_env/lib/python3.8/site-packages/airflow/models/taskinstance.py", line 1458, in _execute_task_with_callbacks
    result = self._execute_task(context, self.task)
  File "/home/dante/DWBI/Apache/py_env/lib/python3.8/site-packages/airflow/models/taskinstance.py", line 1514, in _execute_task
    result = execute_callable(context=context)
  File "/home/dante/DWBI/Apache/py_env/lib/python3.8/site-packages/airflow/decorators/base.py", line 134, in execute
    return_value = super().execute(context)
  File "/home/dante/DWBI/Apache/py_env/lib/python3.8/site-packages/airflow/operators/python.py", line 151, in execute
    return_value = self.execute_callable()
  File "/home/dante/DWBI/Apache/py_env/lib/python3.8/site-packages/airflow/operators/python.py", line 162, in execute_callable
    return self.python_callable(*self.op_args, **self.op_kwargs)
  File "/home/dante/DWBI/Apache/dags/DWBI_HW2_dag.py", line 47, in transform
    dat_2 = data.drop(columns=[['VIN','FuelType']])
AttributeError: 'function' object has no attribute 'drop'
[2021-11-21 20:17:20,480] {local_task_job.py:154} INFO - Task exited with return code 1
[2021-11-21 20:17:20,495] {local_task_job.py:264} INFO - 0 downstream tasks scheduled from follow-on schedule check
