[2021-11-21 20:28:21,040] {taskinstance.py:1035} INFO - Dependencies all met for <TaskInstance: DWBI_HW2_dag.extract manual__2021-11-21T19:17:17.384479+00:00 [queued]>
[2021-11-21 20:28:21,048] {taskinstance.py:1035} INFO - Dependencies all met for <TaskInstance: DWBI_HW2_dag.extract manual__2021-11-21T19:17:17.384479+00:00 [queued]>
[2021-11-21 20:28:21,048] {taskinstance.py:1241} INFO - 
--------------------------------------------------------------------------------
[2021-11-21 20:28:21,048] {taskinstance.py:1242} INFO - Starting attempt 6 of 6
[2021-11-21 20:28:21,048] {taskinstance.py:1243} INFO - 
--------------------------------------------------------------------------------
[2021-11-21 20:28:21,056] {taskinstance.py:1262} INFO - Executing <Task(_PythonDecoratedOperator): extract> on 2021-11-21 19:17:17.384479+00:00
[2021-11-21 20:28:21,059] {standard_task_runner.py:52} INFO - Started process 20133 to run task
[2021-11-21 20:28:21,062] {standard_task_runner.py:76} INFO - Running: ['airflow', 'tasks', 'run', 'DWBI_HW2_dag', 'extract', 'manual__2021-11-21T19:17:17.384479+00:00', '--job-id', '36', '--raw', '--subdir', '/home/dante/DWBI/Apache/dags/DWBI_HW2_dag.py', '--cfg-path', '/tmp/tmp0v3jy08j', '--error-file', '/tmp/tmp5wopili9']
[2021-11-21 20:28:21,063] {standard_task_runner.py:77} INFO - Job 36: Subtask extract
[2021-11-21 20:28:21,085] {logging_mixin.py:109} INFO - Running <TaskInstance: DWBI_HW2_dag.extract manual__2021-11-21T19:17:17.384479+00:00 [running]> on host dj-XPS
[2021-11-21 20:28:21,105] {taskinstance.py:1427} INFO - Exporting the following env vars:
AIRFLOW_CTX_DAG_OWNER=dj
AIRFLOW_CTX_DAG_ID=DWBI_HW2_dag
AIRFLOW_CTX_TASK_ID=extract
AIRFLOW_CTX_EXECUTION_DATE=2021-11-21T19:17:17.384479+00:00
AIRFLOW_CTX_DAG_RUN_ID=manual__2021-11-21T19:17:17.384479+00:00
[2021-11-21 20:28:21,106] {logging_mixin.py:109} INFO - Successfully made contact with the database.
[2021-11-21 20:28:21,106] {taskinstance.py:1703} ERROR - Task failed with exception
Traceback (most recent call last):
  File "/home/dante/DWBI/Apache/py_env/lib/python3.8/site-packages/airflow/models/taskinstance.py", line 1332, in _run_raw_task
    self._execute_task_with_callbacks(context)
  File "/home/dante/DWBI/Apache/py_env/lib/python3.8/site-packages/airflow/models/taskinstance.py", line 1458, in _execute_task_with_callbacks
    result = self._execute_task(context, self.task)
  File "/home/dante/DWBI/Apache/py_env/lib/python3.8/site-packages/airflow/models/taskinstance.py", line 1514, in _execute_task
    result = execute_callable(context=context)
  File "/home/dante/DWBI/Apache/py_env/lib/python3.8/site-packages/airflow/decorators/base.py", line 134, in execute
    return_value = super().execute(context)
  File "/home/dante/DWBI/Apache/py_env/lib/python3.8/site-packages/airflow/operators/python.py", line 151, in execute
    return_value = self.execute_callable()
  File "/home/dante/DWBI/Apache/py_env/lib/python3.8/site-packages/airflow/operators/python.py", line 162, in execute_callable
    return self.python_callable(*self.op_args, **self.op_kwargs)
  File "/home/dante/DWBI/Apache/dags/DWBI_HW2_dag.py", line 35, in extract
    query = cnx.execute(select)
sqlite3.OperationalError: no such table: car
[2021-11-21 20:28:21,111] {taskinstance.py:1270} INFO - Marking task as FAILED. dag_id=DWBI_HW2_dag, task_id=extract, execution_date=20211121T191717, start_date=20211121T192821, end_date=20211121T192821
[2021-11-21 20:28:21,120] {standard_task_runner.py:88} ERROR - Failed to execute job 36 for task extract
Traceback (most recent call last):
  File "/home/dante/DWBI/Apache/py_env/lib/python3.8/site-packages/airflow/task/task_runner/standard_task_runner.py", line 85, in _start_by_fork
    args.func(args, dag=self.dag)
  File "/home/dante/DWBI/Apache/py_env/lib/python3.8/site-packages/airflow/cli/cli_parser.py", line 48, in command
    return func(*args, **kwargs)
  File "/home/dante/DWBI/Apache/py_env/lib/python3.8/site-packages/airflow/utils/cli.py", line 92, in wrapper
    return f(*args, **kwargs)
  File "/home/dante/DWBI/Apache/py_env/lib/python3.8/site-packages/airflow/cli/commands/task_command.py", line 292, in task_run
    _run_task_by_selected_method(args, dag, ti)
  File "/home/dante/DWBI/Apache/py_env/lib/python3.8/site-packages/airflow/cli/commands/task_command.py", line 107, in _run_task_by_selected_method
    _run_raw_task(args, ti)
  File "/home/dante/DWBI/Apache/py_env/lib/python3.8/site-packages/airflow/cli/commands/task_command.py", line 180, in _run_raw_task
    ti._run_raw_task(
  File "/home/dante/DWBI/Apache/py_env/lib/python3.8/site-packages/airflow/utils/session.py", line 70, in wrapper
    return func(*args, session=session, **kwargs)
  File "/home/dante/DWBI/Apache/py_env/lib/python3.8/site-packages/airflow/models/taskinstance.py", line 1332, in _run_raw_task
    self._execute_task_with_callbacks(context)
  File "/home/dante/DWBI/Apache/py_env/lib/python3.8/site-packages/airflow/models/taskinstance.py", line 1458, in _execute_task_with_callbacks
    result = self._execute_task(context, self.task)
  File "/home/dante/DWBI/Apache/py_env/lib/python3.8/site-packages/airflow/models/taskinstance.py", line 1514, in _execute_task
    result = execute_callable(context=context)
  File "/home/dante/DWBI/Apache/py_env/lib/python3.8/site-packages/airflow/decorators/base.py", line 134, in execute
    return_value = super().execute(context)
  File "/home/dante/DWBI/Apache/py_env/lib/python3.8/site-packages/airflow/operators/python.py", line 151, in execute
    return_value = self.execute_callable()
  File "/home/dante/DWBI/Apache/py_env/lib/python3.8/site-packages/airflow/operators/python.py", line 162, in execute_callable
    return self.python_callable(*self.op_args, **self.op_kwargs)
  File "/home/dante/DWBI/Apache/dags/DWBI_HW2_dag.py", line 35, in extract
    query = cnx.execute(select)
sqlite3.OperationalError: no such table: car
[2021-11-21 20:28:21,154] {local_task_job.py:154} INFO - Task exited with return code 1
[2021-11-21 20:28:21,175] {local_task_job.py:264} INFO - 0 downstream tasks scheduled from follow-on schedule check
