[2021-11-21 20:44:10,811] {taskinstance.py:1035} INFO - Dependencies all met for <TaskInstance: DWBI_HW2_dag.transform manual__2021-11-21T19:44:04.588072+00:00 [queued]>
[2021-11-21 20:44:10,821] {taskinstance.py:1035} INFO - Dependencies all met for <TaskInstance: DWBI_HW2_dag.transform manual__2021-11-21T19:44:04.588072+00:00 [queued]>
[2021-11-21 20:44:10,821] {taskinstance.py:1241} INFO - 
--------------------------------------------------------------------------------
[2021-11-21 20:44:10,821] {taskinstance.py:1242} INFO - Starting attempt 1 of 6
[2021-11-21 20:44:10,821] {taskinstance.py:1243} INFO - 
--------------------------------------------------------------------------------
[2021-11-21 20:44:10,832] {taskinstance.py:1262} INFO - Executing <Task(_PythonDecoratedOperator): transform> on 2021-11-21 19:44:04.588072+00:00
[2021-11-21 20:44:10,836] {standard_task_runner.py:52} INFO - Started process 22526 to run task
[2021-11-21 20:44:10,839] {standard_task_runner.py:76} INFO - Running: ['airflow', 'tasks', 'run', 'DWBI_HW2_dag', 'transform', 'manual__2021-11-21T19:44:04.588072+00:00', '--job-id', '39', '--raw', '--subdir', '/home/dante/DWBI/Apache/dags/DWBI_HW2_dag.py', '--cfg-path', '/tmp/tmpi1uvfqzd', '--error-file', '/tmp/tmp44fl35iq']
[2021-11-21 20:44:10,840] {standard_task_runner.py:77} INFO - Job 39: Subtask transform
[2021-11-21 20:44:10,866] {logging_mixin.py:109} INFO - Running <TaskInstance: DWBI_HW2_dag.transform manual__2021-11-21T19:44:04.588072+00:00 [running]> on host dj-XPS
[2021-11-21 20:44:10,896] {taskinstance.py:1427} INFO - Exporting the following env vars:
AIRFLOW_CTX_DAG_OWNER=dj
AIRFLOW_CTX_DAG_ID=DWBI_HW2_dag
AIRFLOW_CTX_TASK_ID=transform
AIRFLOW_CTX_EXECUTION_DATE=2021-11-21T19:44:04.588072+00:00
AIRFLOW_CTX_DAG_RUN_ID=manual__2021-11-21T19:44:04.588072+00:00
[2021-11-21 20:44:10,905] {logging_mixin.py:109} INFO - Successfully fetched the data
[2021-11-21 20:44:10,906] {taskinstance.py:1703} ERROR - Task failed with exception
Traceback (most recent call last):
  File "/home/dante/DWBI/Apache/py_env/lib/python3.8/site-packages/airflow/models/taskinstance.py", line 1332, in _run_raw_task
    self._execute_task_with_callbacks(context)
  File "/home/dante/DWBI/Apache/py_env/lib/python3.8/site-packages/airflow/models/taskinstance.py", line 1458, in _execute_task_with_callbacks
    result = self._execute_task(context, self.task)
  File "/home/dante/DWBI/Apache/py_env/lib/python3.8/site-packages/airflow/models/taskinstance.py", line 1514, in _execute_task
    result = execute_callable(context=context)
  File "/home/dante/DWBI/Apache/py_env/lib/python3.8/site-packages/airflow/decorators/base.py", line 134, in execute
    return_value = super().execute(context)
  File "/home/dante/DWBI/Apache/py_env/lib/python3.8/site-packages/airflow/operators/python.py", line 151, in execute
    return_value = self.execute_callable()
  File "/home/dante/DWBI/Apache/py_env/lib/python3.8/site-packages/airflow/operators/python.py", line 162, in execute_callable
    return self.python_callable(*self.op_args, **self.op_kwargs)
  File "/home/dante/DWBI/Apache/dags/DWBI_HW2_dag.py", line 61, in transform
    dat_2 = data.drop(columns=[['VIN','FuelType']])
  File "/home/dante/DWBI/Apache/py_env/lib/python3.8/site-packages/pandas/util/_decorators.py", line 311, in wrapper
    return func(*args, **kwargs)
  File "/home/dante/DWBI/Apache/py_env/lib/python3.8/site-packages/pandas/core/frame.py", line 4906, in drop
    return super().drop(
  File "/home/dante/DWBI/Apache/py_env/lib/python3.8/site-packages/pandas/core/generic.py", line 4150, in drop
    obj = obj._drop_axis(labels, axis, level=level, errors=errors)
  File "/home/dante/DWBI/Apache/py_env/lib/python3.8/site-packages/pandas/core/generic.py", line 4185, in _drop_axis
    new_axis = axis.drop(labels, errors=errors)
  File "/home/dante/DWBI/Apache/py_env/lib/python3.8/site-packages/pandas/core/indexes/base.py", line 6017, in drop
    raise KeyError(f"{labels[mask]} not found in axis")
KeyError: "[('VIN', 'FuelType')] not found in axis"
[2021-11-21 20:44:10,921] {taskinstance.py:1270} INFO - Marking task as UP_FOR_RETRY. dag_id=DWBI_HW2_dag, task_id=transform, execution_date=20211121T194404, start_date=20211121T194410, end_date=20211121T194410
[2021-11-21 20:44:10,935] {standard_task_runner.py:88} ERROR - Failed to execute job 39 for task transform
Traceback (most recent call last):
  File "/home/dante/DWBI/Apache/py_env/lib/python3.8/site-packages/airflow/task/task_runner/standard_task_runner.py", line 85, in _start_by_fork
    args.func(args, dag=self.dag)
  File "/home/dante/DWBI/Apache/py_env/lib/python3.8/site-packages/airflow/cli/cli_parser.py", line 48, in command
    return func(*args, **kwargs)
  File "/home/dante/DWBI/Apache/py_env/lib/python3.8/site-packages/airflow/utils/cli.py", line 92, in wrapper
    return f(*args, **kwargs)
  File "/home/dante/DWBI/Apache/py_env/lib/python3.8/site-packages/airflow/cli/commands/task_command.py", line 292, in task_run
    _run_task_by_selected_method(args, dag, ti)
  File "/home/dante/DWBI/Apache/py_env/lib/python3.8/site-packages/airflow/cli/commands/task_command.py", line 107, in _run_task_by_selected_method
    _run_raw_task(args, ti)
  File "/home/dante/DWBI/Apache/py_env/lib/python3.8/site-packages/airflow/cli/commands/task_command.py", line 180, in _run_raw_task
    ti._run_raw_task(
  File "/home/dante/DWBI/Apache/py_env/lib/python3.8/site-packages/airflow/utils/session.py", line 70, in wrapper
    return func(*args, session=session, **kwargs)
  File "/home/dante/DWBI/Apache/py_env/lib/python3.8/site-packages/airflow/models/taskinstance.py", line 1332, in _run_raw_task
    self._execute_task_with_callbacks(context)
  File "/home/dante/DWBI/Apache/py_env/lib/python3.8/site-packages/airflow/models/taskinstance.py", line 1458, in _execute_task_with_callbacks
    result = self._execute_task(context, self.task)
  File "/home/dante/DWBI/Apache/py_env/lib/python3.8/site-packages/airflow/models/taskinstance.py", line 1514, in _execute_task
    result = execute_callable(context=context)
  File "/home/dante/DWBI/Apache/py_env/lib/python3.8/site-packages/airflow/decorators/base.py", line 134, in execute
    return_value = super().execute(context)
  File "/home/dante/DWBI/Apache/py_env/lib/python3.8/site-packages/airflow/operators/python.py", line 151, in execute
    return_value = self.execute_callable()
  File "/home/dante/DWBI/Apache/py_env/lib/python3.8/site-packages/airflow/operators/python.py", line 162, in execute_callable
    return self.python_callable(*self.op_args, **self.op_kwargs)
  File "/home/dante/DWBI/Apache/dags/DWBI_HW2_dag.py", line 61, in transform
    dat_2 = data.drop(columns=[['VIN','FuelType']])
  File "/home/dante/DWBI/Apache/py_env/lib/python3.8/site-packages/pandas/util/_decorators.py", line 311, in wrapper
    return func(*args, **kwargs)
  File "/home/dante/DWBI/Apache/py_env/lib/python3.8/site-packages/pandas/core/frame.py", line 4906, in drop
    return super().drop(
  File "/home/dante/DWBI/Apache/py_env/lib/python3.8/site-packages/pandas/core/generic.py", line 4150, in drop
    obj = obj._drop_axis(labels, axis, level=level, errors=errors)
  File "/home/dante/DWBI/Apache/py_env/lib/python3.8/site-packages/pandas/core/generic.py", line 4185, in _drop_axis
    new_axis = axis.drop(labels, errors=errors)
  File "/home/dante/DWBI/Apache/py_env/lib/python3.8/site-packages/pandas/core/indexes/base.py", line 6017, in drop
    raise KeyError(f"{labels[mask]} not found in axis")
KeyError: "[('VIN', 'FuelType')] not found in axis"
[2021-11-21 20:44:10,970] {local_task_job.py:154} INFO - Task exited with return code 1
[2021-11-21 20:44:10,987] {local_task_job.py:264} INFO - 0 downstream tasks scheduled from follow-on schedule check
